<?xml version="1.0"?>
<robot xmlns:xacro="http://www.ros.org/wiki/xacro">
  <!-- Loading some constants -->
  <xacro:include filename="$(find uuv_descriptions)/urdf/common.urdf.xacro"/>
  <!-- Loading file with sensor macros -->
  <xacro:include filename="$(find uuv_sensor_ros_plugins)/urdf/sensor_snippets.xacro"/>
  <!-- Loading the UUV simulator ROS plugin macros -->
  <xacro:include filename="$(find uuv_gazebo_ros_plugins)/urdf/snippets.xacro"/>
  <!-- Loading vehicle's specific macros -->
  <xacro:include filename="$(find deepleng_description)/urdf/snippets.xacro"/>

  <!--
    Vehicle's parameters (remember to enter the model parameters below)
  -->

  <xacro:property name="mass" value="185.0"/> <!--eigentlich 115.957-->
  <!-- Center of gravity -->
  <xacro:property name="cog" value="-0.05811 -0.00029 0.00492"/>
  <!-- Fluid density -->
  <xacro:property name="rho" value="1028"/>

  <!--
    Visual mesh file for the vehicle, usually in DAE (Collada) format. Be sure to store the
    mesh with the origin of the mesh on the same position of the center of mass, otherwise
    the mesh pose will have to be corrected below in the <visual> block.
    Open the meshes for the RexROV vehicle in Blender to see an example on the mesh placement.
  -->

  <!-- Collision geometry mesh, usually in STL format (it is recommended to keep
  this geometry as simple as possible to improve the performance the physics engine
  regarding the computation of collision forces) -->
   <!-- Vehicle macro -->
  <xacro:macro name="deepleng_base" params="namespace *gazebo">

      <!-- Rigid body description of the base link -->
      <link name="${namespace}/base_link">
        <!--
          Be careful to setup the coefficients for the inertial tensor,
          otherwise your model will become unstable on Gazebo
        -->
        <inertial>
          <mass value="${mass}" />
          <origin xyz="${cog}" rpy="0 0 0"/>
          <inertia ixx="1.1368" ixy="0" ixz="0"
                   iyy="87.0" iyz="0"
                   izz="87.0" />
        </inertial>

        <visual>
          <origin xyz="0 0 0" rpy="0 0 0"/>
          <geometry>
            <cylinder length="1.5" radius="0.15"/>
          </geometry>
        </visual>

        <collision>
          <origin xyz="0 0 0" rpy="0 0 0"/>
          <geometry>
            <cylinder length="1" radius="0.1"/>
          </geometry>
        </collision>
      </link>

      <link name="${namespace}/thruster_base">
        <inertial>
          <mass value="0.01" />
          <origin xyz="0.0 0.0 0.0" rpy="0.0 0.0 3.14159"/>
          <inertia ixx="0.001" ixy="0" ixz="0"
                   iyy="0.001" iyz="0"
                   izz="0.001" />
        </inertial>

        <visual>
          <origin xyz="0 0 0" rpy="0 0 3.14159"/>
          <geometry>
            <cylinder length="0.1" radius="0.15"/>
          </geometry>
        </visual>

        <collision>
          <origin xyz="0 0 0" rpy="0 0 3.14159"/>
          <geometry>
            <cylinder length="0.1" radius="0.15"/>
          </geometry>
        </collision>
      </link>

      <joint name="yaw_joint" type="revolute">
        <origin rpy="0.0 0.0 0.0" xyz="-1.325 0 0"/>
        <parent link="${namespace}/base_link"/>
        <child link="${namespace}/help_link"/>
        <axis xyz="0.0 0.0 1.0"/>
        <limit effort="170" lower="-3.0543" upper="3.0543" velocity="1.431"/>
      </joint>

      <joint name="pitch_joint" type="revolute">
        <origin rpy="0.0 0.0 0.0" xyz="0 0 0"/>
        <parent link="${namespace}/help_link"/>
        <child link="${namespace}/thruster_base"/>
        <axis xyz="0.0 1.0 0.0"/>
        <limit effort="170" lower="-3.0543" upper="3.0543" velocity="1.431"/>
      </joint>

      <link name="${namespace}/help_link">
        <inertial>
          <mass value="0.01" />
          <origin xyz="0.0 0.0 0.0" rpy="0.0 0.0 0.0"/>
          <inertia ixx="0.001" ixy="0" ixz="0"
                   iyy="0.001" iyz="0"
                   izz="0.001" />
        </inertial>
      </link>

      <transmission name="yaw_trans">
        <type>transmission_interface/SimpleTransmission</type>
        <joint name="yaw_joint">
          <hardwareInterface>hardware_interface/EffortJointInterface</hardwareInterface>
        </joint>
        <actuator name="yaw_motor">
          <hardwareInterface>EffortJointInterface</hardwareInterface>
          <mechanicalReduction>1</mechanicalReduction>
        </actuator>
      </transmission>

      <transmission name="pitch_trans">
        <type>transmission_interface/SimpleTransmission</type>
        <joint name="pitch_joint">
          <hardwareInterface>hardware_interface/EffortJointInterface</hardwareInterface>
        </joint>
        <actuator name="pitch_motor">
          <hardwareInterface>EffortJointInterface</hardwareInterface>
          <mechanicalReduction>1</mechanicalReduction>
        </actuator>
      </transmission>

    <gazebo reference="${namespace}/base_link">
      <selfCollide>false</selfCollide>
    </gazebo>

    <!-- Set up hydrodynamic plugin given as input parameter -->
    <xacro:insert_block name="gazebo"/>

    <!-- Include the thruster modules -->
    <xacro:include filename="$(find deepleng_description)/urdf/actuators.xacro"/>

    <!-- Include the sensor modules -->
    <xacro:include filename="$(find deepleng_description)/urdf/sensors.xacro"/>

  </xacro:macro>

</robot>
